ERROR:django.request:Internal Server Error: /order/
Traceback (most recent call last):
  File "D:\Web Development\Python\Django\NatBag\NAT-Bags-VU\natBags\natBags\views.py", line 298, in order
    send_email_token(customer_email, token, url)
  File "D:\Web Development\Python\Django\NatBag\NAT-Bags-VU\natBags\natBags\views.py", line 356, in send_email_token
    send_mail(subject, message, email_from, recipients_list)
  File "C:\Users\ADMIN\AppData\Local\Programs\Python\Python311\Lib\site-packages\django\core\mail\__init__.py", line 87, in send_mail
    return mail.send()
           ^^^^^^^^^^^
  File "C:\Users\ADMIN\AppData\Local\Programs\Python\Python311\Lib\site-packages\django\core\mail\message.py", line 298, in send
    return self.get_connection(fail_silently).send_messages([self])
           ^^^^^^^^^^^^^^^^^^^^^^^^^^^^^^^^^^^^^^^^^^^^^^^^^^^^^^^^
  File "C:\Users\ADMIN\AppData\Local\Programs\Python\Python311\Lib\site-packages\django\core\mail\backends\smtp.py", line 127, in send_messages
    new_conn_created = self.open()
                       ^^^^^^^^^^^
  File "C:\Users\ADMIN\AppData\Local\Programs\Python\Python311\Lib\site-packages\django\core\mail\backends\smtp.py", line 94, in open
    self.connection.login(self.username, self.password)
  File "C:\Users\ADMIN\AppData\Local\Programs\Python\Python311\Lib\smtplib.py", line 750, in login
    raise last_exception
  File "C:\Users\ADMIN\AppData\Local\Programs\Python\Python311\Lib\smtplib.py", line 739, in login
    (code, resp) = self.auth(
                   ^^^^^^^^^^
  File "C:\Users\ADMIN\AppData\Local\Programs\Python\Python311\Lib\smtplib.py", line 662, in auth
    raise SMTPAuthenticationError(code, resp)
smtplib.SMTPAuthenticationError: (535, b'5.7.8 Username and Password not accepted. For more information, go to\n5.7.8  https://support.google.com/mail/?p=BadCredentials ffacd0b85a97d-367a0522ea3sm3211198f8f.27 - gsmtp')

During handling of the above exception, another exception occurred:

Traceback (most recent call last):
  File "C:\Users\ADMIN\AppData\Local\Programs\Python\Python311\Lib\site-packages\django\core\handlers\exception.py", line 55, in inner
    response = get_response(request)
               ^^^^^^^^^^^^^^^^^^^^^
  File "C:\Users\ADMIN\AppData\Local\Programs\Python\Python311\Lib\site-packages\django\core\handlers\base.py", line 197, in _get_response
    response = wrapped_callback(request, *callback_args, **callback_kwargs)
               ^^^^^^^^^^^^^^^^^^^^^^^^^^^^^^^^^^^^^^^^^^^^^^^^^^^^^^^^^^^^
  File "D:\Web Development\Python\Django\NatBag\NAT-Bags-VU\natBags\natBags\views.py", line 320, in order
    e.logging.error(f"Check your Internet connection: {e}")
    ^^^^^^^^^
AttributeError: 'SMTPAuthenticationError' object has no attribute 'logging'
WARNING:django.request:Not Found: /favicon.ico
INFO:django.utils.autoreload:D:\Web Development\Python\Django\NatBag\NAT-Bags-VU\natBags\natBags\views.py changed, reloading.
ERROR:root:Error sending email: (535, b'5.7.8 Username and Password not accepted. For more information, go to\n5.7.8  https://support.google.com/mail/?p=BadCredentials 5b1f17b1804b1-4264a1d5116sm55163765e9.10 - gsmtp')
ERROR:django.request:Internal Server Error: /order/
Traceback (most recent call last):
  File "D:\Web Development\Python\Django\NatBag\NAT-Bags-VU\natBags\natBags\views.py", line 298, in order
    send_email_token(customer_email, token, url)
  File "D:\Web Development\Python\Django\NatBag\NAT-Bags-VU\natBags\natBags\views.py", line 356, in send_email_token
    send_mail(subject, message, email_from, recipients_list)
  File "C:\Users\ADMIN\AppData\Local\Programs\Python\Python311\Lib\site-packages\django\core\mail\__init__.py", line 87, in send_mail
    return mail.send()
           ^^^^^^^^^^^
  File "C:\Users\ADMIN\AppData\Local\Programs\Python\Python311\Lib\site-packages\django\core\mail\message.py", line 298, in send
    return self.get_connection(fail_silently).send_messages([self])
           ^^^^^^^^^^^^^^^^^^^^^^^^^^^^^^^^^^^^^^^^^^^^^^^^^^^^^^^^
  File "C:\Users\ADMIN\AppData\Local\Programs\Python\Python311\Lib\site-packages\django\core\mail\backends\smtp.py", line 127, in send_messages
    new_conn_created = self.open()
                       ^^^^^^^^^^^
  File "C:\Users\ADMIN\AppData\Local\Programs\Python\Python311\Lib\site-packages\django\core\mail\backends\smtp.py", line 94, in open
    self.connection.login(self.username, self.password)
  File "C:\Users\ADMIN\AppData\Local\Programs\Python\Python311\Lib\smtplib.py", line 750, in login
    raise last_exception
  File "C:\Users\ADMIN\AppData\Local\Programs\Python\Python311\Lib\smtplib.py", line 739, in login
    (code, resp) = self.auth(
                   ^^^^^^^^^^
  File "C:\Users\ADMIN\AppData\Local\Programs\Python\Python311\Lib\smtplib.py", line 662, in auth
    raise SMTPAuthenticationError(code, resp)
smtplib.SMTPAuthenticationError: (535, b'5.7.8 Username and Password not accepted. For more information, go to\n5.7.8  https://support.google.com/mail/?p=BadCredentials 5b1f17b1804b1-4264a1d5116sm55163765e9.10 - gsmtp')

During handling of the above exception, another exception occurred:

Traceback (most recent call last):
  File "C:\Users\ADMIN\AppData\Local\Programs\Python\Python311\Lib\site-packages\django\core\handlers\exception.py", line 55, in inner
    response = get_response(request)
               ^^^^^^^^^^^^^^^^^^^^^
  File "C:\Users\ADMIN\AppData\Local\Programs\Python\Python311\Lib\site-packages\django\core\handlers\base.py", line 197, in _get_response
    response = wrapped_callback(request, *callback_args, **callback_kwargs)
               ^^^^^^^^^^^^^^^^^^^^^^^^^^^^^^^^^^^^^^^^^^^^^^^^^^^^^^^^^^^^
  File "D:\Web Development\Python\Django\NatBag\NAT-Bags-VU\natBags\natBags\views.py", line 320, in order
    e.logging.error(f"Check your Internet connection: {e}")
    ^^^^^^^^^
AttributeError: 'SMTPAuthenticationError' object has no attribute 'logging'
WARNING:django.request:Not Found: /favicon.ico
INFO:django.utils.autoreload:D:\Web Development\Python\Django\NatBag\NAT-Bags-VU\natBags\natBags\settings.py changed, reloading.
INFO:django.utils.autoreload:D:\Web Development\Python\Django\NatBag\NAT-Bags-VU\natBags\natBags\settings.py changed, reloading.
INFO:django.utils.autoreload:D:\Web Development\Python\Django\NatBag\NAT-Bags-VU\natBags\natBags\settings.py changed, reloading.
INFO:django.utils.autoreload:D:\Web Development\Python\Django\NatBag\NAT-Bags-VU\natBags\natBags\settings.py changed, reloading.
INFO:django.utils.autoreload:D:\Web Development\Python\Django\NatBag\NAT-Bags-VU\natBags\natBags\settings.py changed, reloading.
INFO:django.utils.autoreload:D:\Web Development\Python\Django\NatBag\NAT-Bags-VU\natBags\natBags\settings.py changed, reloading.
ERROR:root:Error sending email: (535, b'5.7.8 Username and Password not accepted. For more information, go to\n5.7.8  https://support.google.com/mail/?p=BadCredentials 5b1f17b1804b1-4264a1f22acsm54509975e9.24 - gsmtp')
ERROR:django.request:Internal Server Error: /order/
Traceback (most recent call last):
  File "D:\Web Development\Python\Django\NatBag\NAT-Bags-VU\natBags\natBags\views.py", line 298, in order
    send_email_token(customer_email, token, url)
  File "D:\Web Development\Python\Django\NatBag\NAT-Bags-VU\natBags\natBags\views.py", line 356, in send_email_token
    send_mail(subject, message, email_from, recipients_list)
  File "C:\Users\ADMIN\AppData\Local\Programs\Python\Python311\Lib\site-packages\django\core\mail\__init__.py", line 87, in send_mail
    return mail.send()
           ^^^^^^^^^^^
  File "C:\Users\ADMIN\AppData\Local\Programs\Python\Python311\Lib\site-packages\django\core\mail\message.py", line 298, in send
    return self.get_connection(fail_silently).send_messages([self])
           ^^^^^^^^^^^^^^^^^^^^^^^^^^^^^^^^^^^^^^^^^^^^^^^^^^^^^^^^
  File "C:\Users\ADMIN\AppData\Local\Programs\Python\Python311\Lib\site-packages\django\core\mail\backends\smtp.py", line 127, in send_messages
    new_conn_created = self.open()
                       ^^^^^^^^^^^
  File "C:\Users\ADMIN\AppData\Local\Programs\Python\Python311\Lib\site-packages\django\core\mail\backends\smtp.py", line 94, in open
    self.connection.login(self.username, self.password)
  File "C:\Users\ADMIN\AppData\Local\Programs\Python\Python311\Lib\smtplib.py", line 750, in login
    raise last_exception
  File "C:\Users\ADMIN\AppData\Local\Programs\Python\Python311\Lib\smtplib.py", line 739, in login
    (code, resp) = self.auth(
                   ^^^^^^^^^^
  File "C:\Users\ADMIN\AppData\Local\Programs\Python\Python311\Lib\smtplib.py", line 662, in auth
    raise SMTPAuthenticationError(code, resp)
smtplib.SMTPAuthenticationError: (535, b'5.7.8 Username and Password not accepted. For more information, go to\n5.7.8  https://support.google.com/mail/?p=BadCredentials 5b1f17b1804b1-4264a1f22acsm54509975e9.24 - gsmtp')

During handling of the above exception, another exception occurred:

Traceback (most recent call last):
  File "C:\Users\ADMIN\AppData\Local\Programs\Python\Python311\Lib\site-packages\django\core\handlers\exception.py", line 55, in inner
    response = get_response(request)
               ^^^^^^^^^^^^^^^^^^^^^
  File "C:\Users\ADMIN\AppData\Local\Programs\Python\Python311\Lib\site-packages\django\core\handlers\base.py", line 197, in _get_response
    response = wrapped_callback(request, *callback_args, **callback_kwargs)
               ^^^^^^^^^^^^^^^^^^^^^^^^^^^^^^^^^^^^^^^^^^^^^^^^^^^^^^^^^^^^
  File "D:\Web Development\Python\Django\NatBag\NAT-Bags-VU\natBags\natBags\views.py", line 320, in order
    e.logging.error(f"Check your Internet connection: {e}")
    ^^^^^^^^^
AttributeError: 'SMTPAuthenticationError' object has no attribute 'logging'
INFO:django.utils.autoreload:D:\Web Development\Python\Django\NatBag\NAT-Bags-VU\natBags\natBags\views.py changed, reloading.
INFO:django.utils.autoreload:D:\Web Development\Python\Django\NatBag\NAT-Bags-VU\natBags\natBags\views.py changed, reloading.
ERROR:root:Error sending email: (535, b'5.7.8 Username and Password not accepted. For more information, go to\n5.7.8  https://support.google.com/mail/?p=BadCredentials 5b1f17b1804b1-426527c0894sm10155355e9.0 - gsmtp')
ERROR:django.request:Internal Server Error: /userRegister/
Traceback (most recent call last):
  File "C:\Users\ADMIN\AppData\Local\Programs\Python\Python311\Lib\site-packages\django\core\handlers\exception.py", line 55, in inner
    response = get_response(request)
               ^^^^^^^^^^^^^^^^^^^^^
  File "C:\Users\ADMIN\AppData\Local\Programs\Python\Python311\Lib\site-packages\django\core\handlers\base.py", line 197, in _get_response
    response = wrapped_callback(request, *callback_args, **callback_kwargs)
               ^^^^^^^^^^^^^^^^^^^^^^^^^^^^^^^^^^^^^^^^^^^^^^^^^^^^^^^^^^^^
  File "D:\Web Development\Python\Django\NatBag\NAT-Bags-VU\natBags\natBags\views.py", line 412, in register
    send_email_token(eml, email_token,url)
  File "D:\Web Development\Python\Django\NatBag\NAT-Bags-VU\natBags\natBags\views.py", line 356, in send_email_token
    send_mail(subject, message, email_from, recipients_list)
  File "C:\Users\ADMIN\AppData\Local\Programs\Python\Python311\Lib\site-packages\django\core\mail\__init__.py", line 87, in send_mail
    return mail.send()
           ^^^^^^^^^^^
  File "C:\Users\ADMIN\AppData\Local\Programs\Python\Python311\Lib\site-packages\django\core\mail\message.py", line 298, in send
    return self.get_connection(fail_silently).send_messages([self])
           ^^^^^^^^^^^^^^^^^^^^^^^^^^^^^^^^^^^^^^^^^^^^^^^^^^^^^^^^
  File "C:\Users\ADMIN\AppData\Local\Programs\Python\Python311\Lib\site-packages\django\core\mail\backends\smtp.py", line 127, in send_messages
    new_conn_created = self.open()
                       ^^^^^^^^^^^
  File "C:\Users\ADMIN\AppData\Local\Programs\Python\Python311\Lib\site-packages\django\core\mail\backends\smtp.py", line 94, in open
    self.connection.login(self.username, self.password)
  File "C:\Users\ADMIN\AppData\Local\Programs\Python\Python311\Lib\smtplib.py", line 750, in login
    raise last_exception
  File "C:\Users\ADMIN\AppData\Local\Programs\Python\Python311\Lib\smtplib.py", line 739, in login
    (code, resp) = self.auth(
                   ^^^^^^^^^^
  File "C:\Users\ADMIN\AppData\Local\Programs\Python\Python311\Lib\smtplib.py", line 662, in auth
    raise SMTPAuthenticationError(code, resp)
smtplib.SMTPAuthenticationError: (535, b'5.7.8 Username and Password not accepted. For more information, go to\n5.7.8  https://support.google.com/mail/?p=BadCredentials 5b1f17b1804b1-426527c0894sm10155355e9.0 - gsmtp')
ERROR:root:Error sending email: (535, b'5.7.8 Username and Password not accepted. For more information, go to\n5.7.8  https://support.google.com/mail/?p=BadCredentials ffacd0b85a97d-36796d4f58csm5322303f8f.58 - gsmtp')
ERROR:django.request:Internal Server Error: /order/
Traceback (most recent call last):
  File "D:\Web Development\Python\Django\NatBag\NAT-Bags-VU\natBags\natBags\views.py", line 298, in order
    send_email_token(customer_email, token, url)
  File "D:\Web Development\Python\Django\NatBag\NAT-Bags-VU\natBags\natBags\views.py", line 356, in send_email_token
    send_mail(subject, message, email_from, recipients_list)
  File "C:\Users\ADMIN\AppData\Local\Programs\Python\Python311\Lib\site-packages\django\core\mail\__init__.py", line 87, in send_mail
    return mail.send()
           ^^^^^^^^^^^
  File "C:\Users\ADMIN\AppData\Local\Programs\Python\Python311\Lib\site-packages\django\core\mail\message.py", line 298, in send
    return self.get_connection(fail_silently).send_messages([self])
           ^^^^^^^^^^^^^^^^^^^^^^^^^^^^^^^^^^^^^^^^^^^^^^^^^^^^^^^^
  File "C:\Users\ADMIN\AppData\Local\Programs\Python\Python311\Lib\site-packages\django\core\mail\backends\smtp.py", line 127, in send_messages
    new_conn_created = self.open()
                       ^^^^^^^^^^^
  File "C:\Users\ADMIN\AppData\Local\Programs\Python\Python311\Lib\site-packages\django\core\mail\backends\smtp.py", line 94, in open
    self.connection.login(self.username, self.password)
  File "C:\Users\ADMIN\AppData\Local\Programs\Python\Python311\Lib\smtplib.py", line 750, in login
    raise last_exception
  File "C:\Users\ADMIN\AppData\Local\Programs\Python\Python311\Lib\smtplib.py", line 739, in login
    (code, resp) = self.auth(
                   ^^^^^^^^^^
  File "C:\Users\ADMIN\AppData\Local\Programs\Python\Python311\Lib\smtplib.py", line 662, in auth
    raise SMTPAuthenticationError(code, resp)
smtplib.SMTPAuthenticationError: (535, b'5.7.8 Username and Password not accepted. For more information, go to\n5.7.8  https://support.google.com/mail/?p=BadCredentials ffacd0b85a97d-36796d4f58csm5322303f8f.58 - gsmtp')

During handling of the above exception, another exception occurred:

Traceback (most recent call last):
  File "C:\Users\ADMIN\AppData\Local\Programs\Python\Python311\Lib\site-packages\django\core\handlers\exception.py", line 55, in inner
    response = get_response(request)
               ^^^^^^^^^^^^^^^^^^^^^
  File "C:\Users\ADMIN\AppData\Local\Programs\Python\Python311\Lib\site-packages\django\core\handlers\base.py", line 197, in _get_response
    response = wrapped_callback(request, *callback_args, **callback_kwargs)
               ^^^^^^^^^^^^^^^^^^^^^^^^^^^^^^^^^^^^^^^^^^^^^^^^^^^^^^^^^^^^
  File "D:\Web Development\Python\Django\NatBag\NAT-Bags-VU\natBags\natBags\views.py", line 320, in order
    e.logging.error(f"Check your Internet connection: {e}")
    ^^^^^^^^^
AttributeError: 'SMTPAuthenticationError' object has no attribute 'logging'
WARNING:django.request:Not Found: /favicon.ico
ERROR:root:Error sending email: (535, b'5.7.8 Username and Password not accepted. For more information, go to\n5.7.8  https://support.google.com/mail/?p=BadCredentials 4fb4d7f45d1cf-5dece1b4e99sm5454754a12.16 - gsmtp')
ERROR:django.request:Internal Server Error: /order/
Traceback (most recent call last):
  File "D:\Web Development\Python\Django\NatBag\NAT-Bags-VU\natBags\natBags\views.py", line 298, in order
    send_email_token(customer_email, token, url)
  File "D:\Web Development\Python\Django\NatBag\NAT-Bags-VU\natBags\natBags\views.py", line 356, in send_email_token
    send_mail(subject, message, email_from, recipients_list)
  File "C:\Users\ADMIN\AppData\Local\Programs\Python\Python311\Lib\site-packages\django\core\mail\__init__.py", line 87, in send_mail
    return mail.send()
           ^^^^^^^^^^^
  File "C:\Users\ADMIN\AppData\Local\Programs\Python\Python311\Lib\site-packages\django\core\mail\message.py", line 298, in send
    return self.get_connection(fail_silently).send_messages([self])
           ^^^^^^^^^^^^^^^^^^^^^^^^^^^^^^^^^^^^^^^^^^^^^^^^^^^^^^^^
  File "C:\Users\ADMIN\AppData\Local\Programs\Python\Python311\Lib\site-packages\django\core\mail\backends\smtp.py", line 127, in send_messages
    new_conn_created = self.open()
                       ^^^^^^^^^^^
  File "C:\Users\ADMIN\AppData\Local\Programs\Python\Python311\Lib\site-packages\django\core\mail\backends\smtp.py", line 94, in open
    self.connection.login(self.username, self.password)
  File "C:\Users\ADMIN\AppData\Local\Programs\Python\Python311\Lib\smtplib.py", line 750, in login
    raise last_exception
  File "C:\Users\ADMIN\AppData\Local\Programs\Python\Python311\Lib\smtplib.py", line 739, in login
    (code, resp) = self.auth(
                   ^^^^^^^^^^
  File "C:\Users\ADMIN\AppData\Local\Programs\Python\Python311\Lib\smtplib.py", line 662, in auth
    raise SMTPAuthenticationError(code, resp)
smtplib.SMTPAuthenticationError: (535, b'5.7.8 Username and Password not accepted. For more information, go to\n5.7.8  https://support.google.com/mail/?p=BadCredentials 4fb4d7f45d1cf-5dece1b4e99sm5454754a12.16 - gsmtp')

During handling of the above exception, another exception occurred:

Traceback (most recent call last):
  File "C:\Users\ADMIN\AppData\Local\Programs\Python\Python311\Lib\site-packages\django\core\handlers\exception.py", line 55, in inner
    response = get_response(request)
               ^^^^^^^^^^^^^^^^^^^^^
  File "C:\Users\ADMIN\AppData\Local\Programs\Python\Python311\Lib\site-packages\django\core\handlers\base.py", line 197, in _get_response
    response = wrapped_callback(request, *callback_args, **callback_kwargs)
               ^^^^^^^^^^^^^^^^^^^^^^^^^^^^^^^^^^^^^^^^^^^^^^^^^^^^^^^^^^^^
  File "D:\Web Development\Python\Django\NatBag\NAT-Bags-VU\natBags\natBags\views.py", line 320, in order
    e.logging.error(f"Check your Internet connection: {e}")
    ^^^^^^^^^
AttributeError: 'SMTPAuthenticationError' object has no attribute 'logging'
INFO:django.utils.autoreload:D:\Web Development\Python\Django\NatBag\NAT-Bags-VU\natBags\natBags\views.py changed, reloading.
INFO:django.utils.autoreload:D:\Web Development\Python\Django\NatBag\NAT-Bags-VU\natBags\natBags\settings.py changed, reloading.
INFO:django.utils.autoreload:D:\Web Development\Python\Django\NatBag\NAT-Bags-VU\natBags\natBags\settings.py changed, reloading.
INFO:django.utils.autoreload:D:\Web Development\Python\Django\NatBag\NAT-Bags-VU\natBags\natBags\settings.py changed, reloading.
INFO:django.utils.autoreload:D:\Web Development\Python\Django\NatBag\NAT-Bags-VU\natBags\natBags\settings.py changed, reloading.
INFO:django.utils.autoreload:D:\Web Development\Python\Django\NatBag\NAT-Bags-VU\natBags\Shop\admin.py changed, reloading.
INFO:django.utils.autoreload:D:\Web Development\Python\Django\NatBag\NAT-Bags-VU\natBags\Shop\admin.py changed, reloading.
INFO:django.utils.autoreload:D:\Web Development\Python\Django\NatBag\NAT-Bags-VU\natBags\Shop\admin.py changed, reloading.
INFO:django.utils.autoreload:D:\Web Development\Python\Django\NatBag\NAT-Bags-VU\natBags\Shop\admin.py changed, reloading.
WARNING:django.request:Not Found: /favicon.ico
WARNING:django.request:Not Found: /favicon.ico
WARNING:django.request:Not Found: /favicon.ico
INFO:django.utils.autoreload:D:\Web Development\Python\Django\NatBag\NAT-Bags-VU\natBags\natBags\settings.py changed, reloading.
INFO:django.utils.autoreload:D:\Web Development\Python\Django\NatBag\NAT-Bags-VU\natBags\natBags\settings.py changed, reloading.
INFO:django.utils.autoreload:D:\Web Development\Python\Django\NatBag\NAT-Bags-VU\natBags\natBags\settings.py changed, reloading.
INFO:django.utils.autoreload:D:\Web Development\Python\Django\NatBag\NAT-Bags-VU\natBags\natBags\wsgi.py changed, reloading.
INFO:django.utils.autoreload:D:\Web Development\Python\Django\NatBag\NAT-Bags-VU\natBags\natBags\settings.py changed, reloading.
INFO:django.utils.autoreload:D:\Web Development\Python\Django\NatBag\NAT-Bags-VU\natBags\natBags\wsgi.py changed, reloading.
INFO:django.utils.autoreload:D:\Web Development\Python\Django\NatBag\NAT-Bags-VU\natBags\natBags\wsgi.py changed, reloading.
INFO:django.utils.autoreload:D:\Web Development\Python\Django\NatBag\NAT-Bags-VU\natBags\natBags\wsgi.py changed, reloading.
INFO:django.utils.autoreload:D:\Web Development\Python\Django\NatBag\NAT-Bags-VU\natBags\natBags\wsgi.py changed, reloading.
WARNING:django.request:Not Found: /Media/products/pexels-luis-quintero-2263817_t5NS60M.jpg
WARNING:django.request:Not Found: /Media/products/korie-cull-QWIJ50qBAJ8-unsplash_WsBwckl.jpg
WARNING:django.request:Not Found: /Media/products/product-img-3_ip6Onqp.jpg
WARNING:django.request:Not Found: /Media/news/news-bg-2.jpg
WARNING:django.request:Not Found: /Media/news/news-bg-6.jpg
WARNING:django.request:Not Found: /Media/news/news-bg-5.jpg
