ERROR:django.request:Internal Server Error: /order/
Traceback (most recent call last):
  File "D:\Web Development\Python\Django\NatBag\NAT-Bags-VU\natBags\natBags\views.py", line 298, in order
    send_email_token(customer_email, token, url)
  File "D:\Web Development\Python\Django\NatBag\NAT-Bags-VU\natBags\natBags\views.py", line 356, in send_email_token
    send_mail(subject, message, email_from, recipients_list)
  File "C:\Users\ADMIN\AppData\Local\Programs\Python\Python311\Lib\site-packages\django\core\mail\__init__.py", line 87, in send_mail
    return mail.send()
           ^^^^^^^^^^^
  File "C:\Users\ADMIN\AppData\Local\Programs\Python\Python311\Lib\site-packages\django\core\mail\message.py", line 298, in send
    return self.get_connection(fail_silently).send_messages([self])
           ^^^^^^^^^^^^^^^^^^^^^^^^^^^^^^^^^^^^^^^^^^^^^^^^^^^^^^^^
  File "C:\Users\ADMIN\AppData\Local\Programs\Python\Python311\Lib\site-packages\django\core\mail\backends\smtp.py", line 127, in send_messages
    new_conn_created = self.open()
                       ^^^^^^^^^^^
  File "C:\Users\ADMIN\AppData\Local\Programs\Python\Python311\Lib\site-packages\django\core\mail\backends\smtp.py", line 94, in open
    self.connection.login(self.username, self.password)
  File "C:\Users\ADMIN\AppData\Local\Programs\Python\Python311\Lib\smtplib.py", line 750, in login
    raise last_exception
  File "C:\Users\ADMIN\AppData\Local\Programs\Python\Python311\Lib\smtplib.py", line 739, in login
    (code, resp) = self.auth(
                   ^^^^^^^^^^
  File "C:\Users\ADMIN\AppData\Local\Programs\Python\Python311\Lib\smtplib.py", line 662, in auth
    raise SMTPAuthenticationError(code, resp)
smtplib.SMTPAuthenticationError: (535, b'5.7.8 Username and Password not accepted. For more information, go to\n5.7.8  https://support.google.com/mail/?p=BadCredentials ffacd0b85a97d-367a0522ea3sm3211198f8f.27 - gsmtp')

During handling of the above exception, another exception occurred:

Traceback (most recent call last):
  File "C:\Users\ADMIN\AppData\Local\Programs\Python\Python311\Lib\site-packages\django\core\handlers\exception.py", line 55, in inner
    response = get_response(request)
               ^^^^^^^^^^^^^^^^^^^^^
  File "C:\Users\ADMIN\AppData\Local\Programs\Python\Python311\Lib\site-packages\django\core\handlers\base.py", line 197, in _get_response
    response = wrapped_callback(request, *callback_args, **callback_kwargs)
               ^^^^^^^^^^^^^^^^^^^^^^^^^^^^^^^^^^^^^^^^^^^^^^^^^^^^^^^^^^^^
  File "D:\Web Development\Python\Django\NatBag\NAT-Bags-VU\natBags\natBags\views.py", line 320, in order
    e.logging.error(f"Check your Internet connection: {e}")
    ^^^^^^^^^
AttributeError: 'SMTPAuthenticationError' object has no attribute 'logging'
WARNING:django.request:Not Found: /favicon.ico
INFO:django.utils.autoreload:D:\Web Development\Python\Django\NatBag\NAT-Bags-VU\natBags\natBags\views.py changed, reloading.
ERROR:root:Error sending email: (535, b'5.7.8 Username and Password not accepted. For more information, go to\n5.7.8  https://support.google.com/mail/?p=BadCredentials 5b1f17b1804b1-4264a1d5116sm55163765e9.10 - gsmtp')
ERROR:django.request:Internal Server Error: /order/
Traceback (most recent call last):
  File "D:\Web Development\Python\Django\NatBag\NAT-Bags-VU\natBags\natBags\views.py", line 298, in order
    send_email_token(customer_email, token, url)
  File "D:\Web Development\Python\Django\NatBag\NAT-Bags-VU\natBags\natBags\views.py", line 356, in send_email_token
    send_mail(subject, message, email_from, recipients_list)
  File "C:\Users\ADMIN\AppData\Local\Programs\Python\Python311\Lib\site-packages\django\core\mail\__init__.py", line 87, in send_mail
    return mail.send()
           ^^^^^^^^^^^
  File "C:\Users\ADMIN\AppData\Local\Programs\Python\Python311\Lib\site-packages\django\core\mail\message.py", line 298, in send
    return self.get_connection(fail_silently).send_messages([self])
           ^^^^^^^^^^^^^^^^^^^^^^^^^^^^^^^^^^^^^^^^^^^^^^^^^^^^^^^^
  File "C:\Users\ADMIN\AppData\Local\Programs\Python\Python311\Lib\site-packages\django\core\mail\backends\smtp.py", line 127, in send_messages
    new_conn_created = self.open()
                       ^^^^^^^^^^^
  File "C:\Users\ADMIN\AppData\Local\Programs\Python\Python311\Lib\site-packages\django\core\mail\backends\smtp.py", line 94, in open
    self.connection.login(self.username, self.password)
  File "C:\Users\ADMIN\AppData\Local\Programs\Python\Python311\Lib\smtplib.py", line 750, in login
    raise last_exception
  File "C:\Users\ADMIN\AppData\Local\Programs\Python\Python311\Lib\smtplib.py", line 739, in login
    (code, resp) = self.auth(
                   ^^^^^^^^^^
  File "C:\Users\ADMIN\AppData\Local\Programs\Python\Python311\Lib\smtplib.py", line 662, in auth
    raise SMTPAuthenticationError(code, resp)
smtplib.SMTPAuthenticationError: (535, b'5.7.8 Username and Password not accepted. For more information, go to\n5.7.8  https://support.google.com/mail/?p=BadCredentials 5b1f17b1804b1-4264a1d5116sm55163765e9.10 - gsmtp')

During handling of the above exception, another exception occurred:

Traceback (most recent call last):
  File "C:\Users\ADMIN\AppData\Local\Programs\Python\Python311\Lib\site-packages\django\core\handlers\exception.py", line 55, in inner
    response = get_response(request)
               ^^^^^^^^^^^^^^^^^^^^^
  File "C:\Users\ADMIN\AppData\Local\Programs\Python\Python311\Lib\site-packages\django\core\handlers\base.py", line 197, in _get_response
    response = wrapped_callback(request, *callback_args, **callback_kwargs)
               ^^^^^^^^^^^^^^^^^^^^^^^^^^^^^^^^^^^^^^^^^^^^^^^^^^^^^^^^^^^^
  File "D:\Web Development\Python\Django\NatBag\NAT-Bags-VU\natBags\natBags\views.py", line 320, in order
    e.logging.error(f"Check your Internet connection: {e}")
    ^^^^^^^^^
AttributeError: 'SMTPAuthenticationError' object has no attribute 'logging'
WARNING:django.request:Not Found: /favicon.ico
INFO:django.utils.autoreload:D:\Web Development\Python\Django\NatBag\NAT-Bags-VU\natBags\natBags\settings.py changed, reloading.
INFO:django.utils.autoreload:D:\Web Development\Python\Django\NatBag\NAT-Bags-VU\natBags\natBags\settings.py changed, reloading.
INFO:django.utils.autoreload:D:\Web Development\Python\Django\NatBag\NAT-Bags-VU\natBags\natBags\settings.py changed, reloading.
INFO:django.utils.autoreload:D:\Web Development\Python\Django\NatBag\NAT-Bags-VU\natBags\natBags\settings.py changed, reloading.
INFO:django.utils.autoreload:D:\Web Development\Python\Django\NatBag\NAT-Bags-VU\natBags\natBags\settings.py changed, reloading.
INFO:django.utils.autoreload:D:\Web Development\Python\Django\NatBag\NAT-Bags-VU\natBags\natBags\settings.py changed, reloading.
ERROR:root:Error sending email: (535, b'5.7.8 Username and Password not accepted. For more information, go to\n5.7.8  https://support.google.com/mail/?p=BadCredentials 5b1f17b1804b1-4264a1f22acsm54509975e9.24 - gsmtp')
ERROR:django.request:Internal Server Error: /order/
Traceback (most recent call last):
  File "D:\Web Development\Python\Django\NatBag\NAT-Bags-VU\natBags\natBags\views.py", line 298, in order
    send_email_token(customer_email, token, url)
  File "D:\Web Development\Python\Django\NatBag\NAT-Bags-VU\natBags\natBags\views.py", line 356, in send_email_token
    send_mail(subject, message, email_from, recipients_list)
  File "C:\Users\ADMIN\AppData\Local\Programs\Python\Python311\Lib\site-packages\django\core\mail\__init__.py", line 87, in send_mail
    return mail.send()
           ^^^^^^^^^^^
  File "C:\Users\ADMIN\AppData\Local\Programs\Python\Python311\Lib\site-packages\django\core\mail\message.py", line 298, in send
    return self.get_connection(fail_silently).send_messages([self])
           ^^^^^^^^^^^^^^^^^^^^^^^^^^^^^^^^^^^^^^^^^^^^^^^^^^^^^^^^
  File "C:\Users\ADMIN\AppData\Local\Programs\Python\Python311\Lib\site-packages\django\core\mail\backends\smtp.py", line 127, in send_messages
    new_conn_created = self.open()
                       ^^^^^^^^^^^
  File "C:\Users\ADMIN\AppData\Local\Programs\Python\Python311\Lib\site-packages\django\core\mail\backends\smtp.py", line 94, in open
    self.connection.login(self.username, self.password)
  File "C:\Users\ADMIN\AppData\Local\Programs\Python\Python311\Lib\smtplib.py", line 750, in login
    raise last_exception
  File "C:\Users\ADMIN\AppData\Local\Programs\Python\Python311\Lib\smtplib.py", line 739, in login
    (code, resp) = self.auth(
                   ^^^^^^^^^^
  File "C:\Users\ADMIN\AppData\Local\Programs\Python\Python311\Lib\smtplib.py", line 662, in auth
    raise SMTPAuthenticationError(code, resp)
smtplib.SMTPAuthenticationError: (535, b'5.7.8 Username and Password not accepted. For more information, go to\n5.7.8  https://support.google.com/mail/?p=BadCredentials 5b1f17b1804b1-4264a1f22acsm54509975e9.24 - gsmtp')

During handling of the above exception, another exception occurred:

Traceback (most recent call last):
  File "C:\Users\ADMIN\AppData\Local\Programs\Python\Python311\Lib\site-packages\django\core\handlers\exception.py", line 55, in inner
    response = get_response(request)
               ^^^^^^^^^^^^^^^^^^^^^
  File "C:\Users\ADMIN\AppData\Local\Programs\Python\Python311\Lib\site-packages\django\core\handlers\base.py", line 197, in _get_response
    response = wrapped_callback(request, *callback_args, **callback_kwargs)
               ^^^^^^^^^^^^^^^^^^^^^^^^^^^^^^^^^^^^^^^^^^^^^^^^^^^^^^^^^^^^
  File "D:\Web Development\Python\Django\NatBag\NAT-Bags-VU\natBags\natBags\views.py", line 320, in order
    e.logging.error(f"Check your Internet connection: {e}")
    ^^^^^^^^^
AttributeError: 'SMTPAuthenticationError' object has no attribute 'logging'
INFO:django.utils.autoreload:D:\Web Development\Python\Django\NatBag\NAT-Bags-VU\natBags\natBags\views.py changed, reloading.
INFO:django.utils.autoreload:D:\Web Development\Python\Django\NatBag\NAT-Bags-VU\natBags\natBags\views.py changed, reloading.
ERROR:root:Error sending email: (535, b'5.7.8 Username and Password not accepted. For more information, go to\n5.7.8  https://support.google.com/mail/?p=BadCredentials 5b1f17b1804b1-426527c0894sm10155355e9.0 - gsmtp')
ERROR:django.request:Internal Server Error: /userRegister/
Traceback (most recent call last):
  File "C:\Users\ADMIN\AppData\Local\Programs\Python\Python311\Lib\site-packages\django\core\handlers\exception.py", line 55, in inner
    response = get_response(request)
               ^^^^^^^^^^^^^^^^^^^^^
  File "C:\Users\ADMIN\AppData\Local\Programs\Python\Python311\Lib\site-packages\django\core\handlers\base.py", line 197, in _get_response
    response = wrapped_callback(request, *callback_args, **callback_kwargs)
               ^^^^^^^^^^^^^^^^^^^^^^^^^^^^^^^^^^^^^^^^^^^^^^^^^^^^^^^^^^^^
  File "D:\Web Development\Python\Django\NatBag\NAT-Bags-VU\natBags\natBags\views.py", line 412, in register
    send_email_token(eml, email_token,url)
  File "D:\Web Development\Python\Django\NatBag\NAT-Bags-VU\natBags\natBags\views.py", line 356, in send_email_token
    send_mail(subject, message, email_from, recipients_list)
  File "C:\Users\ADMIN\AppData\Local\Programs\Python\Python311\Lib\site-packages\django\core\mail\__init__.py", line 87, in send_mail
    return mail.send()
           ^^^^^^^^^^^
  File "C:\Users\ADMIN\AppData\Local\Programs\Python\Python311\Lib\site-packages\django\core\mail\message.py", line 298, in send
    return self.get_connection(fail_silently).send_messages([self])
           ^^^^^^^^^^^^^^^^^^^^^^^^^^^^^^^^^^^^^^^^^^^^^^^^^^^^^^^^
  File "C:\Users\ADMIN\AppData\Local\Programs\Python\Python311\Lib\site-packages\django\core\mail\backends\smtp.py", line 127, in send_messages
    new_conn_created = self.open()
                       ^^^^^^^^^^^
  File "C:\Users\ADMIN\AppData\Local\Programs\Python\Python311\Lib\site-packages\django\core\mail\backends\smtp.py", line 94, in open
    self.connection.login(self.username, self.password)
  File "C:\Users\ADMIN\AppData\Local\Programs\Python\Python311\Lib\smtplib.py", line 750, in login
    raise last_exception
  File "C:\Users\ADMIN\AppData\Local\Programs\Python\Python311\Lib\smtplib.py", line 739, in login
    (code, resp) = self.auth(
                   ^^^^^^^^^^
  File "C:\Users\ADMIN\AppData\Local\Programs\Python\Python311\Lib\smtplib.py", line 662, in auth
    raise SMTPAuthenticationError(code, resp)
smtplib.SMTPAuthenticationError: (535, b'5.7.8 Username and Password not accepted. For more information, go to\n5.7.8  https://support.google.com/mail/?p=BadCredentials 5b1f17b1804b1-426527c0894sm10155355e9.0 - gsmtp')
ERROR:root:Error sending email: (535, b'5.7.8 Username and Password not accepted. For more information, go to\n5.7.8  https://support.google.com/mail/?p=BadCredentials ffacd0b85a97d-36796d4f58csm5322303f8f.58 - gsmtp')
ERROR:django.request:Internal Server Error: /order/
Traceback (most recent call last):
  File "D:\Web Development\Python\Django\NatBag\NAT-Bags-VU\natBags\natBags\views.py", line 298, in order
    send_email_token(customer_email, token, url)
  File "D:\Web Development\Python\Django\NatBag\NAT-Bags-VU\natBags\natBags\views.py", line 356, in send_email_token
    send_mail(subject, message, email_from, recipients_list)
  File "C:\Users\ADMIN\AppData\Local\Programs\Python\Python311\Lib\site-packages\django\core\mail\__init__.py", line 87, in send_mail
    return mail.send()
           ^^^^^^^^^^^
  File "C:\Users\ADMIN\AppData\Local\Programs\Python\Python311\Lib\site-packages\django\core\mail\message.py", line 298, in send
    return self.get_connection(fail_silently).send_messages([self])
           ^^^^^^^^^^^^^^^^^^^^^^^^^^^^^^^^^^^^^^^^^^^^^^^^^^^^^^^^
  File "C:\Users\ADMIN\AppData\Local\Programs\Python\Python311\Lib\site-packages\django\core\mail\backends\smtp.py", line 127, in send_messages
    new_conn_created = self.open()
                       ^^^^^^^^^^^
  File "C:\Users\ADMIN\AppData\Local\Programs\Python\Python311\Lib\site-packages\django\core\mail\backends\smtp.py", line 94, in open
    self.connection.login(self.username, self.password)
  File "C:\Users\ADMIN\AppData\Local\Programs\Python\Python311\Lib\smtplib.py", line 750, in login
    raise last_exception
  File "C:\Users\ADMIN\AppData\Local\Programs\Python\Python311\Lib\smtplib.py", line 739, in login
    (code, resp) = self.auth(
                   ^^^^^^^^^^
  File "C:\Users\ADMIN\AppData\Local\Programs\Python\Python311\Lib\smtplib.py", line 662, in auth
    raise SMTPAuthenticationError(code, resp)
smtplib.SMTPAuthenticationError: (535, b'5.7.8 Username and Password not accepted. For more information, go to\n5.7.8  https://support.google.com/mail/?p=BadCredentials ffacd0b85a97d-36796d4f58csm5322303f8f.58 - gsmtp')

During handling of the above exception, another exception occurred:

Traceback (most recent call last):
  File "C:\Users\ADMIN\AppData\Local\Programs\Python\Python311\Lib\site-packages\django\core\handlers\exception.py", line 55, in inner
    response = get_response(request)
               ^^^^^^^^^^^^^^^^^^^^^
  File "C:\Users\ADMIN\AppData\Local\Programs\Python\Python311\Lib\site-packages\django\core\handlers\base.py", line 197, in _get_response
    response = wrapped_callback(request, *callback_args, **callback_kwargs)
               ^^^^^^^^^^^^^^^^^^^^^^^^^^^^^^^^^^^^^^^^^^^^^^^^^^^^^^^^^^^^
  File "D:\Web Development\Python\Django\NatBag\NAT-Bags-VU\natBags\natBags\views.py", line 320, in order
    e.logging.error(f"Check your Internet connection: {e}")
    ^^^^^^^^^
AttributeError: 'SMTPAuthenticationError' object has no attribute 'logging'
WARNING:django.request:Not Found: /favicon.ico
ERROR:root:Error sending email: (535, b'5.7.8 Username and Password not accepted. For more information, go to\n5.7.8  https://support.google.com/mail/?p=BadCredentials 4fb4d7f45d1cf-5dece1b4e99sm5454754a12.16 - gsmtp')
ERROR:django.request:Internal Server Error: /order/
Traceback (most recent call last):
  File "D:\Web Development\Python\Django\NatBag\NAT-Bags-VU\natBags\natBags\views.py", line 298, in order
    send_email_token(customer_email, token, url)
  File "D:\Web Development\Python\Django\NatBag\NAT-Bags-VU\natBags\natBags\views.py", line 356, in send_email_token
    send_mail(subject, message, email_from, recipients_list)
  File "C:\Users\ADMIN\AppData\Local\Programs\Python\Python311\Lib\site-packages\django\core\mail\__init__.py", line 87, in send_mail
    return mail.send()
           ^^^^^^^^^^^
  File "C:\Users\ADMIN\AppData\Local\Programs\Python\Python311\Lib\site-packages\django\core\mail\message.py", line 298, in send
    return self.get_connection(fail_silently).send_messages([self])
           ^^^^^^^^^^^^^^^^^^^^^^^^^^^^^^^^^^^^^^^^^^^^^^^^^^^^^^^^
  File "C:\Users\ADMIN\AppData\Local\Programs\Python\Python311\Lib\site-packages\django\core\mail\backends\smtp.py", line 127, in send_messages
    new_conn_created = self.open()
                       ^^^^^^^^^^^
  File "C:\Users\ADMIN\AppData\Local\Programs\Python\Python311\Lib\site-packages\django\core\mail\backends\smtp.py", line 94, in open
    self.connection.login(self.username, self.password)
  File "C:\Users\ADMIN\AppData\Local\Programs\Python\Python311\Lib\smtplib.py", line 750, in login
    raise last_exception
  File "C:\Users\ADMIN\AppData\Local\Programs\Python\Python311\Lib\smtplib.py", line 739, in login
    (code, resp) = self.auth(
                   ^^^^^^^^^^
  File "C:\Users\ADMIN\AppData\Local\Programs\Python\Python311\Lib\smtplib.py", line 662, in auth
    raise SMTPAuthenticationError(code, resp)
smtplib.SMTPAuthenticationError: (535, b'5.7.8 Username and Password not accepted. For more information, go to\n5.7.8  https://support.google.com/mail/?p=BadCredentials 4fb4d7f45d1cf-5dece1b4e99sm5454754a12.16 - gsmtp')

During handling of the above exception, another exception occurred:

Traceback (most recent call last):
  File "C:\Users\ADMIN\AppData\Local\Programs\Python\Python311\Lib\site-packages\django\core\handlers\exception.py", line 55, in inner
    response = get_response(request)
               ^^^^^^^^^^^^^^^^^^^^^
  File "C:\Users\ADMIN\AppData\Local\Programs\Python\Python311\Lib\site-packages\django\core\handlers\base.py", line 197, in _get_response
    response = wrapped_callback(request, *callback_args, **callback_kwargs)
               ^^^^^^^^^^^^^^^^^^^^^^^^^^^^^^^^^^^^^^^^^^^^^^^^^^^^^^^^^^^^
  File "D:\Web Development\Python\Django\NatBag\NAT-Bags-VU\natBags\natBags\views.py", line 320, in order
    e.logging.error(f"Check your Internet connection: {e}")
    ^^^^^^^^^
AttributeError: 'SMTPAuthenticationError' object has no attribute 'logging'
INFO:django.utils.autoreload:D:\Web Development\Python\Django\NatBag\NAT-Bags-VU\natBags\natBags\views.py changed, reloading.
INFO:django.utils.autoreload:D:\Web Development\Python\Django\NatBag\NAT-Bags-VU\natBags\natBags\settings.py changed, reloading.
INFO:django.utils.autoreload:D:\Web Development\Python\Django\NatBag\NAT-Bags-VU\natBags\natBags\settings.py changed, reloading.
INFO:django.utils.autoreload:D:\Web Development\Python\Django\NatBag\NAT-Bags-VU\natBags\natBags\settings.py changed, reloading.
INFO:django.utils.autoreload:D:\Web Development\Python\Django\NatBag\NAT-Bags-VU\natBags\natBags\settings.py changed, reloading.
INFO:django.utils.autoreload:D:\Web Development\Python\Django\NatBag\NAT-Bags-VU\natBags\Shop\admin.py changed, reloading.
INFO:django.utils.autoreload:D:\Web Development\Python\Django\NatBag\NAT-Bags-VU\natBags\Shop\admin.py changed, reloading.
INFO:django.utils.autoreload:D:\Web Development\Python\Django\NatBag\NAT-Bags-VU\natBags\Shop\admin.py changed, reloading.
INFO:django.utils.autoreload:D:\Web Development\Python\Django\NatBag\NAT-Bags-VU\natBags\Shop\admin.py changed, reloading.
WARNING:django.request:Not Found: /favicon.ico
WARNING:django.request:Not Found: /favicon.ico
WARNING:django.request:Not Found: /favicon.ico
INFO:django.utils.autoreload:D:\Web Development\Python\Django\NatBag\NAT-Bags-VU\natBags\natBags\settings.py changed, reloading.
INFO:django.utils.autoreload:D:\Web Development\Python\Django\NatBag\NAT-Bags-VU\natBags\natBags\settings.py changed, reloading.
INFO:django.utils.autoreload:D:\Web Development\Python\Django\NatBag\NAT-Bags-VU\natBags\natBags\settings.py changed, reloading.
INFO:django.utils.autoreload:D:\Web Development\Python\Django\NatBag\NAT-Bags-VU\natBags\natBags\wsgi.py changed, reloading.
INFO:django.utils.autoreload:D:\Web Development\Python\Django\NatBag\NAT-Bags-VU\natBags\natBags\settings.py changed, reloading.
INFO:django.utils.autoreload:D:\Web Development\Python\Django\NatBag\NAT-Bags-VU\natBags\natBags\wsgi.py changed, reloading.
INFO:django.utils.autoreload:D:\Web Development\Python\Django\NatBag\NAT-Bags-VU\natBags\natBags\wsgi.py changed, reloading.
INFO:django.utils.autoreload:D:\Web Development\Python\Django\NatBag\NAT-Bags-VU\natBags\natBags\wsgi.py changed, reloading.
INFO:django.utils.autoreload:D:\Web Development\Python\Django\NatBag\NAT-Bags-VU\natBags\natBags\wsgi.py changed, reloading.
WARNING:django.request:Not Found: /Media/products/pexels-luis-quintero-2263817_t5NS60M.jpg
WARNING:django.request:Not Found: /Media/products/korie-cull-QWIJ50qBAJ8-unsplash_WsBwckl.jpg
WARNING:django.request:Not Found: /Media/products/product-img-3_ip6Onqp.jpg
WARNING:django.request:Not Found: /Media/news/news-bg-2.jpg
WARNING:django.request:Not Found: /Media/news/news-bg-6.jpg
WARNING:django.request:Not Found: /Media/news/news-bg-5.jpg
WARNING:django.request:Not Found: /Media/products/pexels-luis-quintero-2263817_t5NS60M.jpg
WARNING:django.request:Not Found: /Media/products/korie-cull-QWIJ50qBAJ8-unsplash_WsBwckl.jpg
WARNING:django.request:Not Found: /Media/products/product-img-3_ip6Onqp.jpg
WARNING:django.request:Not Found: /Media/news/news-bg-2.jpg
WARNING:django.request:Not Found: /Media/news/news-bg-6.jpg
WARNING:django.request:Not Found: /Media/news/news-bg-5.jpg
WARNING:django.request:Not Found: /favicon.ico
ERROR:django.security.DisallowedHost:Invalid HTTP_HOST header: '192.168.74.229:8000'. You may need to add '192.168.74.229' to ALLOWED_HOSTS.
Traceback (most recent call last):
  File "C:\Users\ADMIN\AppData\Local\Programs\Python\Python311\Lib\site-packages\django\core\handlers\exception.py", line 55, in inner
    response = get_response(request)
               ^^^^^^^^^^^^^^^^^^^^^
  File "C:\Users\ADMIN\AppData\Local\Programs\Python\Python311\Lib\site-packages\django\utils\deprecation.py", line 119, in __call__
    response = self.process_request(request)
               ^^^^^^^^^^^^^^^^^^^^^^^^^^^^^
  File "C:\Users\ADMIN\AppData\Local\Programs\Python\Python311\Lib\site-packages\django\middleware\common.py", line 48, in process_request
    host = request.get_host()
           ^^^^^^^^^^^^^^^^^^
  File "C:\Users\ADMIN\AppData\Local\Programs\Python\Python311\Lib\site-packages\django\http\request.py", line 191, in get_host
    raise DisallowedHost(msg)
django.core.exceptions.DisallowedHost: Invalid HTTP_HOST header: '192.168.74.229:8000'. You may need to add '192.168.74.229' to ALLOWED_HOSTS.
ERROR:django.security.DisallowedHost:Invalid HTTP_HOST header: '192.168.74.229:8000'. You may need to add '192.168.74.229' to ALLOWED_HOSTS.
Traceback (most recent call last):
  File "C:\Users\ADMIN\AppData\Local\Programs\Python\Python311\Lib\site-packages\django\core\handlers\exception.py", line 55, in inner
    response = get_response(request)
               ^^^^^^^^^^^^^^^^^^^^^
  File "C:\Users\ADMIN\AppData\Local\Programs\Python\Python311\Lib\site-packages\django\utils\deprecation.py", line 119, in __call__
    response = self.process_request(request)
               ^^^^^^^^^^^^^^^^^^^^^^^^^^^^^
  File "C:\Users\ADMIN\AppData\Local\Programs\Python\Python311\Lib\site-packages\django\middleware\common.py", line 48, in process_request
    host = request.get_host()
           ^^^^^^^^^^^^^^^^^^
  File "C:\Users\ADMIN\AppData\Local\Programs\Python\Python311\Lib\site-packages\django\http\request.py", line 191, in get_host
    raise DisallowedHost(msg)
django.core.exceptions.DisallowedHost: Invalid HTTP_HOST header: '192.168.74.229:8000'. You may need to add '192.168.74.229' to ALLOWED_HOSTS.
ERROR:django.security.DisallowedHost:Invalid HTTP_HOST header: '192.168.74.229:8000'. You may need to add '192.168.74.229' to ALLOWED_HOSTS.
Traceback (most recent call last):
  File "C:\Users\ADMIN\AppData\Local\Programs\Python\Python311\Lib\site-packages\django\core\handlers\exception.py", line 55, in inner
    response = get_response(request)
               ^^^^^^^^^^^^^^^^^^^^^
  File "C:\Users\ADMIN\AppData\Local\Programs\Python\Python311\Lib\site-packages\django\utils\deprecation.py", line 119, in __call__
    response = self.process_request(request)
               ^^^^^^^^^^^^^^^^^^^^^^^^^^^^^
  File "C:\Users\ADMIN\AppData\Local\Programs\Python\Python311\Lib\site-packages\django\middleware\common.py", line 48, in process_request
    host = request.get_host()
           ^^^^^^^^^^^^^^^^^^
  File "C:\Users\ADMIN\AppData\Local\Programs\Python\Python311\Lib\site-packages\django\http\request.py", line 191, in get_host
    raise DisallowedHost(msg)
django.core.exceptions.DisallowedHost: Invalid HTTP_HOST header: '192.168.74.229:8000'. You may need to add '192.168.74.229' to ALLOWED_HOSTS.
ERROR:django.security.DisallowedHost:Invalid HTTP_HOST header: '192.168.74.229:8000'. You may need to add '192.168.74.229' to ALLOWED_HOSTS.
Traceback (most recent call last):
  File "C:\Users\ADMIN\AppData\Local\Programs\Python\Python311\Lib\site-packages\django\core\handlers\exception.py", line 55, in inner
    response = get_response(request)
               ^^^^^^^^^^^^^^^^^^^^^
  File "C:\Users\ADMIN\AppData\Local\Programs\Python\Python311\Lib\site-packages\django\utils\deprecation.py", line 119, in __call__
    response = self.process_request(request)
               ^^^^^^^^^^^^^^^^^^^^^^^^^^^^^
  File "C:\Users\ADMIN\AppData\Local\Programs\Python\Python311\Lib\site-packages\django\middleware\common.py", line 48, in process_request
    host = request.get_host()
           ^^^^^^^^^^^^^^^^^^
  File "C:\Users\ADMIN\AppData\Local\Programs\Python\Python311\Lib\site-packages\django\http\request.py", line 191, in get_host
    raise DisallowedHost(msg)
django.core.exceptions.DisallowedHost: Invalid HTTP_HOST header: '192.168.74.229:8000'. You may need to add '192.168.74.229' to ALLOWED_HOSTS.
INFO:django.utils.autoreload:D:\Web Development\Python\Django\NatBag\NAT-Bags-VU\natBags\natBags\settings.py changed, reloading.
INFO:django.utils.autoreload:D:\Web Development\Python\Django\NatBag\NAT-Bags-VU\natBags\natBags\settings.py changed, reloading.
INFO:django.utils.autoreload:D:\Web Development\Python\Django\NatBag\NAT-Bags-VU\natBags\natBags\settings.py changed, reloading.
INFO:django.utils.autoreload:D:\Web Development\Python\Django\NatBag\NAT-Bags-VU\natBags\natBags\settings.py changed, reloading.
INFO:django.utils.autoreload:D:\Web Development\Python\Django\NatBag\NAT-Bags-VU\natBags\natBags\settings.py changed, reloading.
WARNING:django.request:Not Found: /Media/products/korie-cull-QWIJ50qBAJ8-unsplash_WsBwckl.jpg
WARNING:django.request:Not Found: /Media/products/pexels-luis-quintero-2263817_t5NS60M.jpg
WARNING:django.request:Not Found: /Media/products/product-img-3_ip6Onqp.jpg
WARNING:django.request:Not Found: /Media/news/news-bg-2.jpg
WARNING:django.request:Not Found: /Media/news/news-bg-6.jpg
WARNING:django.request:Not Found: /Media/news/news-bg-5.jpg
WARNING:django.request:Not Found: /Media/products/pexels-luis-quintero-2263817_t5NS60M.jpg
WARNING:django.request:Not Found: /Media/products/korie-cull-QWIJ50qBAJ8-unsplash_WsBwckl.jpg
WARNING:django.request:Not Found: /Media/products/product-img-3_ip6Onqp.jpg
WARNING:django.request:Not Found: /Media/products/pexels-skylar-kang-6044266_EN8o1nm.jpg
WARNING:django.request:Not Found: /Media/products/product-img-6.jpg
WARNING:django.request:Not Found: /Media/products/adejoke-drilling-XBqD7PZp5mQ-unsplash_W0w5RIm.jpg
WARNING:django.request:Not Found: /Media/products/k8-VCuSV_UJbBU-unsplash_ON34qft.jpg
WARNING:django.request:Not Found: /Media/products/pexels-cottonbro-studio-6532099_JJmLeRV.jpg
WARNING:django.request:Not Found: /Media/products/mostafa-mahmoudi-J4DnKxz_3sA-unsplash_gv9aqY8.jpg
WARNING:django.request:Not Found: /Media/products/pexels-luis-quintero-2263817_t5NS60M.jpg
WARNING:django.request:Not Found: /Media/products/korie-cull-QWIJ50qBAJ8-unsplash_WsBwckl.jpg
WARNING:django.request:Not Found: /Media/products/product-img-3_ip6Onqp.jpg
WARNING:django.request:Not Found: /Media/news/news-bg-5.jpg
WARNING:django.request:Not Found: /Media/news/news-bg-2.jpg
WARNING:django.request:Not Found: /Media/news/news-bg-6.jpg
WARNING:django.request:Not Found: /Media/products/korie-cull-QWIJ50qBAJ8-unsplash_WsBwckl.jpg
WARNING:django.request:Not Found: /Media/products/pexels-luis-quintero-2263817_t5NS60M.jpg
WARNING:django.request:Not Found: /Media/products/product-img-3_ip6Onqp.jpg
WARNING:django.request:Not Found: /Media/products/pexels-skylar-kang-6044266_EN8o1nm.jpg
WARNING:django.request:Not Found: /Media/products/adejoke-drilling-XBqD7PZp5mQ-unsplash_W0w5RIm.jpg
WARNING:django.request:Not Found: /Media/products/product-img-6.jpg
WARNING:django.request:Not Found: /Media/products/k8-VCuSV_UJbBU-unsplash_ON34qft.jpg
WARNING:django.request:Not Found: /Media/products/pexels-cottonbro-studio-6532099_JJmLeRV.jpg
WARNING:django.request:Not Found: /Media/products/mostafa-mahmoudi-J4DnKxz_3sA-unsplash_gv9aqY8.jpg
WARNING:django.request:Not Found: /favicon.ico
WARNING:django.request:Not Found: /media/products/kelly-sikkema-1Pgq9ZpIatI-unsplash.jpg
WARNING:django.request:Not Found: /media/static/css/all.min.css
WARNING:django.request:Not Found: /media/static/css/owl.carousel.css
WARNING:django.request:Not Found: /media/static/bootstrap/css/bootstrap.min.css
WARNING:django.request:Not Found: /media/static/css/magnific-popup.css
WARNING:django.request:Not Found: /media/static/css/meanmenu.min.css
WARNING:django.request:Not Found: /media/static/css/animate.css
WARNING:django.request:Not Found: /media/static/css/main.css
WARNING:django.request:Not Found: /media/static/css/responsive.css
WARNING:django.request:Not Found: /media/static/img/logo.png
WARNING:django.request:Not Found: /media/static/img/company-logos/1.png
WARNING:django.request:Not Found: /media/static/img/company-logos/2.png
WARNING:django.request:Not Found: /media/static/js/jquery-1.11.3.min.js
WARNING:django.request:Not Found: /media/static/bootstrap/js/bootstrap.min.js
WARNING:django.request:Not Found: /media/static/img/company-logos/3.png
WARNING:django.request:Not Found: /media/static/img/company-logos/4.png
WARNING:django.request:Not Found: /media/static/js/jquery.countdown.js
WARNING:django.request:Not Found: /media/static/js/jquery.isotope-3.0.6.min.js
WARNING:django.request:Not Found: /media/static/js/waypoints.js
WARNING:django.request:Not Found: /media/static/js/owl.carousel.min.js
WARNING:django.request:Not Found: /media/static/js/jquery.meanmenu.min.js
WARNING:django.request:Not Found: /media/static/js/sticker.js
WARNING:django.request:Not Found: /media/static/js/jquery.magnific-popup.min.js
WARNING:django.request:Not Found: /media/static/img/company-logos/5.png
WARNING:django.request:Not Found: /media/static/js/main.js
WARNING:django.request:Not Found: /media/static/img/favicon.png
WARNING:django.request:Not Found: /media/products/product-img-6.jpg
WARNING:django.request:Not Found: /media/static/css/all.min.css
WARNING:django.request:Not Found: /media/static/bootstrap/css/bootstrap.min.css
WARNING:django.request:Not Found: /media/static/css/owl.carousel.css
WARNING:django.request:Not Found: /media/static/css/magnific-popup.css
WARNING:django.request:Not Found: /media/static/css/animate.css
WARNING:django.request:Not Found: /media/static/css/main.css
WARNING:django.request:Not Found: /media/static/css/responsive.css
WARNING:django.request:Not Found: /media/static/css/meanmenu.min.css
WARNING:django.request:Not Found: /media/static/img/company-logos/1.png
WARNING:django.request:Not Found: /media/static/img/logo.png
WARNING:django.request:Not Found: /media/static/img/company-logos/4.png
WARNING:django.request:Not Found: /media/static/bootstrap/js/bootstrap.min.js
WARNING:django.request:Not Found: /media/static/js/jquery-1.11.3.min.js
WARNING:django.request:Not Found: /media/static/img/company-logos/2.png
WARNING:django.request:Not Found: /media/static/js/jquery.countdown.js
WARNING:django.request:Not Found: /media/static/img/company-logos/3.png
WARNING:django.request:Not Found: /media/static/img/company-logos/5.png
WARNING:django.request:Not Found: /media/static/js/waypoints.js
WARNING:django.request:Not Found: /media/static/js/sticker.js
WARNING:django.request:Not Found: /media/static/js/jquery.isotope-3.0.6.min.js
WARNING:django.request:Not Found: /media/static/js/jquery.magnific-popup.min.js
WARNING:django.request:Not Found: /media/static/js/jquery.meanmenu.min.js
WARNING:django.request:Not Found: /media/static/js/owl.carousel.min.js
WARNING:django.request:Not Found: /media/static/js/main.js
INFO:django.utils.autoreload:D:\Web Development\Python\Django\NatBag\NAT-Bags-VU\natBags\natBags\settings.py changed, reloading.
WARNING:django.request:Not Found: /Media/products/pexels-luis-quintero-2263817_t5NS60M.jpg
WARNING:django.request:Not Found: /Media/products/korie-cull-QWIJ50qBAJ8-unsplash_WsBwckl.jpg
WARNING:django.request:Not Found: /Media/products/product-img-3_ip6Onqp.jpg
WARNING:django.request:Not Found: /Media/news/news-bg-2.jpg
WARNING:django.request:Not Found: /Media/news/news-bg-6.jpg
WARNING:django.request:Not Found: /Media/news/news-bg-5.jpg
WARNING:django.request:Not Found: /Media/products/pexels-luis-quintero-2263817_t5NS60M.jpg
WARNING:django.request:Not Found: /Media/products/product-img-3_ip6Onqp.jpg
WARNING:django.request:Not Found: /Media/products/korie-cull-QWIJ50qBAJ8-unsplash_WsBwckl.jpg
WARNING:django.request:Not Found: /Media/news/news-bg-2.jpg
WARNING:django.request:Not Found: /Media/news/news-bg-6.jpg
WARNING:django.request:Not Found: /Media/news/news-bg-5.jpg
